<?xml version="1.0" ?>
<robot name="roarm_m3_multiprim">
  <material name="black">
    <color rgba="0.1 0.1 0.1 1.0"/>
  </material>
  <material name="dark_gray">
    <color rgba="0.3 0.3 0.3 1.0"/>
  </material>
  <material name="silver">
    <color rgba="0.7 0.7 0.75 1.0"/>
  </material>
  <material name="gray">
    <color rgba="0.5 0.5 0.5 1.0"/>
  </material>
  <link name="world"/>
  <link name="base_link">
    <visual>
      <origin xyz="0 0 0.01" rpy="0 0 0"/>
      <geometry>
        <box size="0.09 0.09 0.02"/>
      </geometry>
      <material name="dark_gray"/>
    </visual>
    <visual>
      <origin xyz="0 0 0.03" rpy="0 0 0"/>
      <geometry>
        <cylinder radius="0.025" length="0.02"/>
      </geometry>
      <material name="black"/>
    </visual>
    <visual>
      <origin xyz="0.03 0 0.015" rpy="0 0 0"/>
      <geometry>
        <box size="0.01 0.08 0.03"/>
      </geometry>
      <material name="dark_gray"/>
    </visual>
    <visual>
      <origin xyz="-0.03 0 0.015" rpy="0 0 0"/>
      <geometry>
        <box size="0.01 0.08 0.03"/>
      </geometry>
      <material name="dark_gray"/>
    </visual>
    <collision>
      <origin xyz="0 0 0.01" rpy="0 0 0"/>
      <geometry>
        <box size="0.09 0.09 0.02"/>
      </geometry>
    </collision>
    <collision>
      <origin xyz="0 0 0.03" rpy="0 0 0"/>
      <geometry>
        <cylinder radius="0.025" length="0.02"/>
      </geometry>
    </collision>
    <inertial>
      <mass value="0.5000"/>
      <origin xyz="0 0 0.03" rpy="0 0 0"/>
      <inertia ixx="0.00035000" iyy="0.00035000" izz="0.00040000" ixy="0.00000000" ixz="0.00000000" iyz="0.00000000"/>
    </inertial>
  </link>
  <link name="link_1">
    <visual>
      <origin xyz="0 0 0.04" rpy="0 0 0"/>
      <geometry>
        <cylinder radius="0.025" length="0.08"/>
      </geometry>
      <material name="black"/>
    </visual>
    <visual>
      <origin xyz="0 0 0.005" rpy="0 0 0"/>
      <geometry>
        <box size="0.04 0.04 0.01"/>
      </geometry>
      <material name="silver"/>
    </visual>
    <collision>
      <origin xyz="0 0 0.04" rpy="0 0 0"/>
      <geometry>
        <cylinder radius="0.025" length="0.08"/>
      </geometry>
    </collision>
    <inertial>
      <mass value="0.3000"/>
      <origin xyz="0 0 0.04" rpy="0 0 0"/>
      <inertia ixx="0.00025187" iyy="0.00025187" izz="0.00018375" ixy="0.00000000" ixz="0.00000000" iyz="0.00000000"/>
    </inertial>
  </link>
  <link name="link_2">
    <visual>
      <origin xyz="0.08 0 0" rpy="0 1.57 0"/>
      <geometry>
        <cylinder radius="0.022" length="0.12"/>
      </geometry>
      <material name="silver"/>
    </visual>
    <visual>
      <origin xyz="0.04 0 0" rpy="0 1.57 0"/>
      <geometry>
        <cylinder radius="0.018" length="0.08"/>
      </geometry>
      <material name="black"/>
    </visual>
    <visual>
      <origin xyz="0.16 0 0" rpy="0 0 0"/>
      <geometry>
        <box size="0.03 0.04 0.04"/>
      </geometry>
      <material name="dark_gray"/>
    </visual>
    <collision>
      <origin xyz="0.08 0 0" rpy="0 1.57 0"/>
      <geometry>
        <cylinder radius="0.025" length="0.16"/>
      </geometry>
    </collision>
    <inertial>
      <mass value="0.2500"/>
      <origin xyz="0.08 0 0" rpy="0 0 0"/>
      <inertia ixx="0.00030000" iyy="0.00150000" izz="0.00150000" ixy="0.00000000" ixz="0.00000000" iyz="0.00000000"/>
    </inertial>
  </link>
  <link name="link_3">
    <visual>
      <origin xyz="0.075 0 0" rpy="0 1.57 0"/>
      <geometry>
        <cylinder radius="0.02" length="0.11"/>
      </geometry>
      <material name="black"/>
    </visual>
    <visual>
      <origin xyz="0.04 0 0" rpy="0 1.57 0"/>
      <geometry>
        <cylinder radius="0.016" length="0.08"/>
      </geometry>
      <material name="silver"/>
    </visual>
    <visual>
      <origin xyz="0.15 0 0" rpy="0 0 0"/>
      <geometry>
        <box size="0.025 0.035 0.035"/>
      </geometry>
      <material name="dark_gray"/>
    </visual>
    <collision>
      <origin xyz="0.075 0 0" rpy="0 1.57 0"/>
      <geometry>
        <cylinder radius="0.02" length="0.15"/>
      </geometry>
    </collision>
    <inertial>
      <mass value="0.2000"/>
      <origin xyz="0.075 0 0" rpy="0 0 0"/>
      <inertia ixx="0.00020833" iyy="0.00044708" izz="0.00044708" ixy="0.00000000" ixz="0.00000000" iyz="0.00000000"/>
    </inertial>
  </link>
  <link name="link_4">
    <visual>
      <origin xyz="0 0 0.03" rpy="0 0 0"/>
      <geometry>
        <cylinder radius="0.018" length="0.06"/>
      </geometry>
      <material name="silver"/>
    </visual>
    <visual>
      <origin xyz="0 0 0.02" rpy="0 0 0"/>
      <geometry>
        <cylinder radius="0.015" length="0.04"/>
      </geometry>
      <material name="black"/>
    </visual>
    <collision>
      <origin xyz="0 0 0.03" rpy="0 0 0"/>
      <geometry>
        <cylinder radius="0.018" length="0.06"/>
      </geometry>
    </collision>
    <inertial>
      <mass value="0.1500"/>
      <origin xyz="0 0 0.03" rpy="0 0 0"/>
      <inertia ixx="0.00002250" iyy="0.00019125" izz="0.00019125" ixy="0.00000000" ixz="0.00000000" iyz="0.00000000"/>
    </inertial>
  </link>
  <link name="link_5">
    <visual>
      <origin xyz="0 0 0.03" rpy="0 0 0"/>
      <geometry>
        <cylinder radius="0.02" length="0.05"/>
      </geometry>
      <material name="black"/>
    </visual>
    <visual>
      <origin xyz="0 0 0.06" rpy="0 0 0"/>
      <geometry>
        <box size="0.035 0.035 0.015"/>
      </geometry>
      <material name="dark_gray"/>
    </visual>
    <collision>
      <origin xyz="0 0 0.03" rpy="0 0 0"/>
      <geometry>
        <cylinder radius="0.02" length="0.06"/>
      </geometry>
    </collision>
    <inertial>
      <mass value="0.1000"/>
      <origin xyz="0 0 0.03" rpy="0 0 0"/>
      <inertia ixx="0.00004563" iyy="0.00004563" izz="0.00003125" ixy="0.00000000" ixz="0.00000000" iyz="0.00000000"/>
    </inertial>
  </link>
  <link name="gripper_base">
    <visual>
      <origin xyz="0 0 0.01" rpy="0 0 0"/>
      <geometry>
        <box size="0.05 0.05 0.02"/>
      </geometry>
      <material name="dark_gray"/>
    </visual>
    <visual>
      <origin xyz="0 0 0.025" rpy="0 0 0"/>
      <geometry>
        <cylinder radius="0.015" length="0.01"/>
      </geometry>
      <material name="black"/>
    </visual>
    <visual>
      <origin xyz="0 0.015 0.01" rpy="0 0 0"/>
      <geometry>
        <box size="0.04 0.01 0.015"/>
      </geometry>
      <material name="silver"/>
    </visual>
    <collision>
      <origin xyz="0 0 0.015" rpy="0 0 0"/>
      <geometry>
        <box size="0.05 0.05 0.03"/>
      </geometry>
    </collision>
    <inertial>
      <mass value="0.0500"/>
      <origin xyz="0 0 0.01" rpy="0 0 0"/>
      <inertia ixx="0.00000833" iyy="0.00001667" izz="0.00002167" ixy="0.00000000" ixz="0.00000000" iyz="0.00000000"/>
    </inertial>
  </link>
  <link name="gripper_left_finger">
    <!-- 그리퍼 베이스 (원통형) -->
    <visual>
      <origin xyz="0 0 0.015" rpy="0 0 0"/>
      <geometry>
        <cylinder radius="0.006" length="0.030"/>
      </geometry>
      <material name="black"/>
    </visual>
    <!-- 그리퍼 팁 (박스형 - 접촉 면적 증가) -->
    <visual>
      <origin xyz="0 0 0.035" rpy="0 0 0"/>
      <geometry>
        <box size="0.020 0.010 0.010"/>
      </geometry>
      <material name="silver"/>
    </visual>
    <!-- 충돌 geometry: 복합 형태 -->
    <collision>
      <origin xyz="0 0 0.015" rpy="0 0 0"/>
      <geometry>
        <cylinder radius="0.006" length="0.030"/>
      </geometry>
    </collision>
    <collision>
      <origin xyz="0 0 0.035" rpy="0 0 0"/>
      <geometry>
        <box size="0.020 0.010 0.010"/>
      </geometry>
    </collision>
    <inertial>
      <mass value="0.0100"/>
      <origin xyz="0 0 0.020" rpy="0 0 0"/>
      <inertia ixx="0.00000150" iyy="0.00000120" izz="0.00000040" ixy="0.00000000" ixz="0.00000000" iyz="0.00000000"/>
    </inertial>
  </link>
  <link name="gripper_right_finger">
    <!-- 그리퍼 베이스 (원통형) -->
    <visual>
      <origin xyz="0 0 0.015" rpy="0 0 0"/>
      <geometry>
        <cylinder radius="0.006" length="0.030"/>
      </geometry>
      <material name="black"/>
    </visual>
    <!-- 그리퍼 팁 (박스형 - 접촉 면적 증가) -->
    <visual>
      <origin xyz="0 0 0.035" rpy="0 0 0"/>
      <geometry>
        <box size="0.020 0.010 0.010"/>
      </geometry>
      <material name="silver"/>
    </visual>
    <!-- 충돌 geometry: 복합 형태 -->
    <collision>
      <origin xyz="0 0 0.015" rpy="0 0 0"/>
      <geometry>
        <cylinder radius="0.006" length="0.030"/>
      </geometry>
    </collision>
    <collision>
      <origin xyz="0 0 0.035" rpy="0 0 0"/>
      <geometry>
        <box size="0.020 0.010 0.010"/>
      </geometry>
    </collision>
    <inertial>
      <mass value="0.0100"/>
      <origin xyz="0 0 0.020" rpy="0 0 0"/>
      <inertia ixx="0.00000150" iyy="0.00000120" izz="0.00000040" ixy="0.00000000" ixz="0.00000000" iyz="0.00000000"/>
    </inertial>
  </link>
  <joint name="world_to_base" type="fixed">
    <parent link="world"/>
    <child link="base_link"/>
    <origin xyz="0 0 0" rpy="0 0 0"/>
  </joint>
  <joint name="joint_1" type="revolute">
    <parent link="base_link"/>
    <child link="link_1"/>
    <origin xyz="0 0 0.06" rpy="0 0 0"/>
    <axis xyz="0 0 1"/>
    <limit lower="-3.14159" upper="3.14159" effort="10" velocity="2.0"/>
    <dynamics damping="0.8" friction="0.5"/>
  </joint>
  <joint name="joint_2" type="revolute">
    <parent link="link_1"/>
    <child link="link_2"/>
    <origin xyz="0 0 0.08" rpy="0 0 0"/>
    <axis xyz="0 1 0"/>
    <limit lower="-3.14159" upper="3.14159" effort="15" velocity="1.5"/>
    <dynamics damping="0.7" friction="0.4"/>
  </joint>
  <joint name="joint_3" type="revolute">
    <parent link="link_2"/>
    <child link="link_3"/>
    <origin xyz="0.16 0 0" rpy="0 0 0"/>
    <axis xyz="0 1 0"/>
    <limit lower="-3.14159" upper="3.14159" effort="10" velocity="2.0"/>
    <dynamics damping="0.6" friction="0.35"/>
  </joint>
  <joint name="joint_4" type="revolute">
    <parent link="link_3"/>
    <child link="link_4"/>
    <origin xyz="0.15 0 0" rpy="0 0 0"/>
    <axis xyz="0 1 0"/>
    <limit lower="-3.14159" upper="3.14159" effort="8" velocity="2.5"/>
    <dynamics damping="0.5" friction="0.3"/>
  </joint>
  <joint name="joint_5" type="revolute">
    <parent link="link_4"/>
    <child link="link_5"/>
    <origin xyz="0 0 0.06" rpy="0 0 0"/>
    <axis xyz="0 0 1"/>
    <limit lower="-3.14159" upper="3.14159" effort="5" velocity="3.0"/>
    <dynamics damping="0.4" friction="0.25"/>
  </joint>
  <joint name="joint_6" type="revolute">
    <parent link="link_5"/>
    <child link="gripper_base"/>
    <origin xyz="0 0 0.065" rpy="0 0 0"/>
    <axis xyz="0 0 1"/>
    <limit lower="-3.14159" upper="3.14159" effort="3" velocity="2.0"/>
    <dynamics damping="0.3" friction="0.2"/>
  </joint>
  <joint name="gripper_left_joint" type="prismatic">
    <parent link="gripper_base"/>
    <child link="gripper_left_finger"/>
    <origin xyz="0 0.015 0.03" rpy="0 0 0"/>
    <axis xyz="0 1 0"/>
    <limit lower="0" upper="0.025" effort="8" velocity="0.08"/>
    <dynamics damping="0.8" friction="0.6"/>
  </joint>
  <joint name="gripper_right_joint" type="prismatic">
    <parent link="gripper_base"/>
    <child link="gripper_right_finger"/>
    <origin xyz="0 -0.015 0.03" rpy="0 0 0"/>
    <axis xyz="0 -1 0"/>
    <limit lower="0" upper="0.025" effort="8" velocity="0.08"/>
    <dynamics damping="0.8" friction="0.6"/>
  </joint>
</robot>
