<?xml version='1.0' encoding='utf-8'?>
<robot name="roarm_m3">
  <material name="black">
    <color rgba="0.1 0.1 0.1 1.0" />
  </material>
  <material name="gray">
    <color rgba="0.5 0.5 0.5 1.0" />
  </material>
  <material name="silver">
    <color rgba="0.75 0.75 0.75 1.0" />
  </material>
  <material name="white">
    <color rgba="0.9 0.9 0.9 1.0" />
  </material>
  <link name="world" />
  <joint name="world_to_base" type="fixed">
    <parent link="world" />
    <child link="base_link" />
    <origin xyz="0 0 0" rpy="0 0 0" />
  </joint>
  <link name="base_link">
    <inertial>
      <mass value="0.5" />
      <origin xyz="0 0 0.03" rpy="0 0 0" />
      <inertia ixx="0.001" iyy="0.001" izz="0.001" ixy="0" ixz="0" iyz="0" />
    </inertial>
    <visual>
      <origin xyz="0 0 0" rpy="0 0 0" />
      <geometry>
        <mesh filename="/home/roarm_m3/roarm_isaac_clean/assets/roarm_m3/meshes/visual/base_link.stl" scale="0.001 0.001 0.001" />
      </geometry>
      <material name="black" />
    </visual>
    <collision>
      <origin xyz="0 0 0.03" rpy="0 0 0" />
      <geometry>
        <cylinder radius="0.055" length="0.06" />
      </geometry>
    </collision>
  </link>
  <joint name="joint_1" type="continuous">
    <parent link="base_link" />
    <child link="link_1" />
    <origin xyz="0 0 0.06" rpy="0 0 0" />
    <axis xyz="0 0 1" />
    <limit effort="10.0" velocity="3.14" />
    <dynamics damping="0.5" friction="0.1" />
  </joint>
  <link name="link_1">
    <inertial>
      <mass value="0.3" />
      <origin xyz="0 0 0.04" rpy="0 0 0" />
      <inertia ixx="0.0008" iyy="0.0008" izz="0.0004" ixy="0" ixz="0" iyz="0" />
    </inertial>
    <visual>
      <origin xyz="0 0 0" rpy="0 0 0" />
      <geometry>
        <mesh filename="/home/roarm_m3/roarm_isaac_clean/assets/roarm_m3/meshes/visual/link_1.stl" scale="0.001 0.001 0.001" />
      </geometry>
      <material name="gray" />
    </visual>
    <collision>
      <origin xyz="0 0 0.04" rpy="0 0 0" />
      <geometry>
        <cylinder radius="0.045" length="0.08" />
      </geometry>
    </collision>
  </link>
  <joint name="joint_2" type="revolute">
    <parent link="link_1" />
    <child link="link_2" />
    <origin xyz="0 0 0.08" rpy="0 0 0" />
    <axis xyz="0 1 0" />
    <limit lower="-1.57" upper="1.57" effort="15.0" velocity="2.62" />
    <dynamics damping="0.7" friction="0.15" />
  </joint>
  <link name="link_2">
    <inertial>
      <mass value="0.4" />
      <origin xyz="0.08 0 0" rpy="0 1.57 0" />
      <inertia ixx="0.002" iyy="0.0025" izz="0.0008" ixy="0" ixz="0" iyz="0" />
    </inertial>
    <visual>
      <origin xyz="0 0 0" rpy="0 0 0" />
      <geometry>
        <mesh filename="/home/roarm_m3/roarm_isaac_clean/assets/roarm_m3/meshes/visual/link_2.stl" scale="0.001 0.001 0.001" />
      </geometry>
      <material name="gray" />
    </visual>
    <collision>
      <origin xyz="0.08 0 0" rpy="0 1.57 0" />
      <geometry>
        <cylinder radius="0.022" length="0.16" />
      </geometry>
    </collision>
  </link>
  <joint name="joint_3" type="revolute">
    <parent link="link_2" />
    <child link="link_3" />
    <origin xyz="0.16 0 0" rpy="0 0 0" />
    <axis xyz="0 1 0" />
    <limit lower="-1.57" upper="1.57" effort="10.0" velocity="2.62" />
    <dynamics damping="0.5" friction="0.1" />
  </joint>
  <link name="link_3">
    <inertial>
      <mass value="0.25" />
      <origin xyz="0.075 0 0" rpy="0 1.57 0" />
      <inertia ixx="0.0012" iyy="0.0015" izz="0.0005" ixy="0" ixz="0" iyz="0" />
    </inertial>
    <visual>
      <origin xyz="0 0 0" rpy="0 0 0" />
      <geometry>
        <mesh filename="/home/roarm_m3/roarm_isaac_clean/assets/roarm_m3/meshes/visual/link_3.stl" scale="0.001 0.001 0.001" />
      </geometry>
      <material name="gray" />
    </visual>
    <collision>
      <origin xyz="0.075 0 0" rpy="0 1.57 0" />
      <geometry>
        <cylinder radius="0.018" length="0.15" />
      </geometry>
    </collision>
  </link>
  <joint name="joint_4" type="revolute">
    <parent link="link_3" />
    <child link="link_4" />
    <origin xyz="0.15 0 0" rpy="0 0 0" />
    <axis xyz="0 1 0" />
    <limit lower="-1.57" upper="1.57" effort="5.0" velocity="3.14" />
    <dynamics damping="0.3" friction="0.05" />
  </joint>
  <link name="link_4">
    <inertial>
      <mass value="0.15" />
      <origin xyz="0.03 0 0" rpy="0 1.57 0" />
      <inertia ixx="0.0003" iyy="0.0004" izz="0.0002" ixy="0" ixz="0" iyz="0" />
    </inertial>
    <visual>
      <origin xyz="0 0 0" rpy="0 0 0" />
      <geometry>
        <mesh filename="/home/roarm_m3/roarm_isaac_clean/assets/roarm_m3/meshes/visual/link_4.stl" scale="0.001 0.001 0.001" />
      </geometry>
      <material name="silver" />
    </visual>
    <collision>
      <origin xyz="0.03 0 0" rpy="0 1.57 0" />
      <geometry>
        <cylinder radius="0.013" length="0.06" />
      </geometry>
    </collision>
  </link>
  <joint name="joint_5" type="continuous">
    <parent link="link_4" />
    <child link="link_5" />
    <origin xyz="0.06 0 0" rpy="0 0 0" />
    <axis xyz="1 0 0" />
    <limit effort="3.0" velocity="3.14" />
    <dynamics damping="0.2" friction="0.03" />
  </joint>
  <link name="link_5">
    <inertial>
      <mass value="0.1" />
      <origin xyz="0.02 0 0" rpy="0 1.57 0" />
      <inertia ixx="0.0001" iyy="0.0001" izz="0.0001" ixy="0" ixz="0" iyz="0" />
    </inertial>
    <visual>
      <origin xyz="0 0 0" rpy="0 0 0" />
      <geometry>
        <mesh filename="/home/roarm_m3/roarm_isaac_clean/assets/roarm_m3/meshes/visual/link_5.stl" scale="0.001 0.001 0.001" />
      </geometry>
      <material name="silver" />
    </visual>
    <collision>
      <origin xyz="0.02 0 0" rpy="0 1.57 0" />
      <geometry>
        <cylinder radius="0.01" length="0.04" />
      </geometry>
    </collision>
  </link>
  <joint name="joint_6" type="revolute">
    <parent link="link_5" />
    <child link="gripper_base" />
    <origin xyz="0.04 0 0" rpy="0 0 0" />
    <axis xyz="0 0 1" />
    <limit lower="1.08" upper="3.14" effort="2.0" velocity="2.0" />
    <dynamics damping="0.1" friction="0.02" />
  </joint>
  <link name="gripper_base">
    <inertial>
      <mass value="0.05" />
      <origin xyz="0 0 0.02" rpy="0 0 0" />
      <inertia ixx="0.00005" iyy="0.00005" izz="0.00003" ixy="0" ixz="0" iyz="0" />
    </inertial>
    <visual>
      <origin xyz="0 0 0.02" rpy="0 0 0" />
      <geometry>
        <mesh filename="/home/roarm_m3/roarm_isaac_clean/assets/roarm_m3/meshes/visual/gripper_base.stl" scale="0.001 0.001 0.001" />
      </geometry>
      <material name="black" />
    </visual>
    <collision>
      <origin xyz="0 0 0.02" rpy="0 0 0" />
      <geometry>
        <box size="0.025 0.018 0.04" />
      </geometry>
    </collision>
  </link>
  <joint name="gripper_left_finger_joint" type="fixed">
    <parent link="gripper_base" />
    <child link="gripper_left_finger" />
    <origin xyz="0 0.015 0.04" rpy="0 0 0" />
  </joint>
  <link name="gripper_left_finger">
    <inertial>
      <mass value="0.01" />
      <origin xyz="0 0 0.015" rpy="0 0 0" />
      <inertia ixx="0.000005" iyy="0.000005" izz="0.000002" ixy="0" ixz="0" iyz="0" />
    </inertial>
    <visual>
      <origin xyz="0 0 0.015" rpy="0 0 0" />
      <geometry>
        <mesh filename="/home/roarm_m3/roarm_isaac_clean/assets/roarm_m3/meshes/visual/gripper_left_finger.stl" scale="0.001 0.001 0.001" />
      </geometry>
      <material name="white" />
    </visual>
    <collision>
      <origin xyz="0 0 0.015" rpy="0 0 0" />
      <geometry>
        <box size="0.008 0.004 0.03" />
      </geometry>
    </collision>
  </link>
  <joint name="gripper_right_finger_joint" type="fixed">
    <parent link="gripper_base" />
    <child link="gripper_right_finger" />
    <origin xyz="0 -0.015 0.04" rpy="0 0 0" />
  </joint>
  <link name="gripper_right_finger">
    <inertial>
      <mass value="0.01" />
      <origin xyz="0 0 0.015" rpy="0 0 0" />
      <inertia ixx="0.000005" iyy="0.000005" izz="0.000002" ixy="0" ixz="0" iyz="0" />
    </inertial>
    <visual>
      <origin xyz="0 0 0.015" rpy="0 0 0" />
      <geometry>
        <mesh filename="/home/roarm_m3/roarm_isaac_clean/assets/roarm_m3/meshes/visual/gripper_right_finger.stl" scale="0.001 0.001 0.001" />
      </geometry>
      <material name="white" />
    </visual>
    <collision>
      <origin xyz="0 0 0.015" rpy="0 0 0" />
      <geometry>
        <box size="0.008 0.004 0.03" />
      </geometry>
    </collision>
  </link>
  <joint name="gripper_to_tcp" type="fixed">
    <parent link="gripper_base" />
    <child link="tcp" />
    <origin xyz="0 0 0.07" rpy="0 0 0" />
  </joint>
  <link name="tcp">
    
  </link>
</robot>
