<?xml version='1.0' encoding='utf-8'?>
<robot name="roarm_m3">

  
  <material name="black"><color rgba="0.1 0.1 0.1 1.0" /></material>
  <material name="gray"><color rgba="0.5 0.5 0.5 1.0" /></material>
  <material name="silver"><color rgba="0.75 0.75 0.75 1.0" /></material>

  
  <link name="world" />
  
  <joint name="world_to_base" type="fixed">
    <parent link="world" />
    <child link="base_link" />
    <origin xyz="0 0 0" rpy="0 0 0" />
  </joint>

  
  <link name="base_link">
    <visual><origin xyz="0 0 0" rpy="0 0 0" /><geometry><mesh filename="file:///home/roarm_m3/roarm_isaac_clean/assets/roarm_m3/meshes/visual/base_link.stl" scale="1 1 1" /></geometry><material name="gray" /></visual><collision><origin xyz="0 0 0" rpy="0 0 0" /><geometry><mesh filename="file:///home/roarm_m3/roarm_isaac_clean/assets/roarm_m3/meshes/collision/base_link.stl" scale="1 1 1" /></geometry></collision><inertial><mass value="0.5000" /><origin xyz="0.0000 0.0000 0.0300" rpy="0 0 0" /><inertia ixx="0.00035000" iyy="0.00035000" izz="0.00040000" ixy="0.00000000" ixz="0.00000000" iyz="0.00000000" /></inertial></link>

  
  <joint name="joint_1" type="revolute">
    <parent link="base_link" />
    <child link="link_1" />
    <origin xyz="0 0 0.060" rpy="0 0 0" />
    <axis xyz="0 0 1" />
    <limit lower="-3.14159" upper="3.14159" effort="10" velocity="2.0" />
    <dynamics damping="0.5" friction="0.3" />
  </joint>

  
  <link name="link_1">
    <visual><origin xyz="0 0 0" rpy="0 0 0" /><geometry><mesh filename="file:///home/roarm_m3/roarm_isaac_clean/assets/roarm_m3/meshes/visual/link_1.stl" scale="1 1 1" /></geometry><material name="gray" /></visual><collision><origin xyz="0 0 0" rpy="0 0 0" /><geometry><mesh filename="file:///home/roarm_m3/roarm_isaac_clean/assets/roarm_m3/meshes/collision/link_1.stl" scale="1 1 1" /></geometry></collision><inertial><mass value="0.3000" /><origin xyz="0.0000 0.0000 0.0400" rpy="0 0 0" /><inertia ixx="0.00025187" iyy="0.00025187" izz="0.00018375" ixy="0.00000000" ixz="0.00000000" iyz="0.00000000" /></inertial></link>

  
  <joint name="joint_2" type="revolute">
    <parent link="link_1" />
    <child link="link_2" />
    <origin xyz="0 0 0.080" rpy="0 0 0" />
    <axis xyz="0 1 0" />
    <limit lower="-1.57" upper="1.57" effort="15" velocity="1.5" />
    <dynamics damping="0.7" friction="0.4" />
  </joint>

  
  <link name="link_2">
    <visual><origin xyz="0 0 0" rpy="0 0 0" /><geometry><mesh filename="file:///home/roarm_m3/roarm_isaac_clean/assets/roarm_m3/meshes/visual/link_2.stl" scale="1 1 1" /></geometry><material name="gray" /></visual><collision><origin xyz="0 0 0" rpy="0 0 0" /><geometry><mesh filename="file:///home/roarm_m3/roarm_isaac_clean/assets/roarm_m3/meshes/collision/link_2.stl" scale="1 1 1" /></geometry></collision><inertial><mass value="0.2500" /><origin xyz="0.0000 0.0000 0.0000" rpy="0 0 0" /><inertia ixx="0.00006667" iyy="0.00056667" izz="0.00056667" ixy="0.00000000" ixz="0.00000000" iyz="0.00000000" /></inertial></link>

  
  <joint name="joint_3" type="revolute">
    <parent link="link_2" />
    <child link="link_3" />
    <origin xyz="0.160 0 0" rpy="0 0 0" />
    <axis xyz="0 1 0" />
    <limit lower="-1.57" upper="1.57" effort="10" velocity="2.0" />
    <dynamics damping="0.5" friction="0.3" />
  </joint>

  
  <link name="link_3">
    <visual><origin xyz="0 0 0" rpy="0 0 0" /><geometry><mesh filename="file:///home/roarm_m3/roarm_isaac_clean/assets/roarm_m3/meshes/visual/link_3.stl" scale="1 1 1" /></geometry><material name="gray" /></visual><collision><origin xyz="0 0 0" rpy="0 0 0" /><geometry><mesh filename="file:///home/roarm_m3/roarm_isaac_clean/assets/roarm_m3/meshes/collision/link_3.stl" scale="1 1 1" /></geometry></collision><inertial><mass value="0.2000" /><origin xyz="0.0000 0.0000 0.0000" rpy="0 0 0" /><inertia ixx="0.00004083" iyy="0.00044708" izz="0.00044708" ixy="0.00000000" ixz="0.00000000" iyz="0.00000000" /></inertial></link>

  
  <joint name="joint_4" type="revolute">
    <parent link="link_3" />
    <child link="link_4" />
    <origin xyz="0.150 0 0" rpy="0 0 0" />
    <axis xyz="0 1 0" />
    <limit lower="-1.57" upper="1.57" effort="5" velocity="2.5" />
    <dynamics damping="0.3" friction="0.2" />
  </joint>

  
  <link name="link_4">
    <visual><origin xyz="0 0 0" rpy="0 0 0" /><geometry><mesh filename="file:///home/roarm_m3/roarm_isaac_clean/assets/roarm_m3/meshes/visual/link_4.stl" scale="1 1 1" /></geometry><material name="gray" /></visual><collision><origin xyz="0 0 0" rpy="0 0 0" /><geometry><mesh filename="file:///home/roarm_m3/roarm_isaac_clean/assets/roarm_m3/meshes/collision/link_4.stl" scale="1 1 1" /></geometry></collision><inertial><mass value="0.1500" /><origin xyz="0.0000 0.0000 0.0000" rpy="0 0 0" /><inertia ixx="0.00002250" iyy="0.00019125" izz="0.00019125" ixy="0.00000000" ixz="0.00000000" iyz="0.00000000" /></inertial></link>

  
  <joint name="joint_5" type="revolute">
    <parent link="link_4" />
    <child link="link_5" />
    <origin xyz="0.060 0 0" rpy="0 0 0" />
    <axis xyz="1 0 0" />
    <limit lower="-3.14159" upper="3.14159" effort="3" velocity="3.0" />
    <dynamics damping="0.2" friction="0.1" />
  </joint>

  
  <link name="link_5">
    <visual><origin xyz="0 0 0" rpy="0 0 0" /><geometry><mesh filename="file:///home/roarm_m3/roarm_isaac_clean/assets/roarm_m3/meshes/visual/link_5.stl" scale="1 1 1" /></geometry><material name="gray" /></visual><collision><origin xyz="0 0 0" rpy="0 0 0" /><geometry><mesh filename="file:///home/roarm_m3/roarm_isaac_clean/assets/roarm_m3/meshes/collision/link_5.stl" scale="1 1 1" /></geometry></collision><inertial><mass value="0.1000" /><origin xyz="0.0000 0.0000 0.0300" rpy="0 0 0" /><inertia ixx="0.00004563" iyy="0.00004563" izz="0.00003125" ixy="0.00000000" ixz="0.00000000" iyz="0.00000000" /></inertial></link>

  
  <joint name="joint_6" type="fixed">
    <parent link="link_5" />
    <child link="gripper_base" />
    <origin xyz="0.040 0 0" rpy="0 0 0" />
  </joint>

  
  <link name="gripper_base">
    <visual><origin xyz="0 0 0" rpy="0 0 0" /><geometry><mesh filename="file:///home/roarm_m3/roarm_isaac_clean/assets/roarm_m3/meshes/visual/gripper_base.stl" scale="1 1 1" /></geometry><material name="gray" /></visual><collision><origin xyz="0 0 0" rpy="0 0 0" /><geometry><mesh filename="file:///home/roarm_m3/roarm_isaac_clean/assets/roarm_m3/meshes/collision/gripper_base.stl" scale="1 1 1" /></geometry></collision><inertial><mass value="0.0500" /><origin xyz="0.0000 0.0000 0.0000" rpy="0 0 0" /><inertia ixx="0.00000833" iyy="0.00001667" izz="0.00002167" ixy="0.00000000" ixz="0.00000000" iyz="0.00000000" /></inertial></link>

  
  <joint name="gripper_left_finger_joint" type="revolute">
    <parent link="gripper_base" />
    <child link="gripper_left_finger" />
    <origin xyz="0 0.015 0.040" rpy="0 0 0" />
    <axis xyz="0 1 0" />
    <limit lower="1.08" upper="3.14" effort="2" velocity="1.0" />
    <dynamics damping="0.1" friction="0.05" />
  </joint>

  
  <link name="gripper_left_finger">
    <visual><origin xyz="0 0 0" rpy="0 0 0" /><geometry><mesh filename="file:///home/roarm_m3/roarm_isaac_clean/assets/roarm_m3/meshes/visual/gripper_left_finger.stl" scale="1 1 1" /></geometry><material name="gray" /></visual><collision><origin xyz="0 0 0" rpy="0 0 0" /><geometry><mesh filename="file:///home/roarm_m3/roarm_isaac_clean/assets/roarm_m3/meshes/collision/gripper_left_finger.stl" scale="1 1 1" /></geometry></collision><inertial><mass value="0.0100" /><origin xyz="0.0000 0.0000 0.0000" rpy="0 0 0" /><inertia ixx="0.00000167" iyy="0.00000142" izz="0.00000042" ixy="0.00000000" ixz="0.00000000" iyz="0.00000000" /></inertial></link>

  
  <joint name="gripper_right_finger_joint" type="revolute">
    <parent link="gripper_base" />
    <child link="gripper_right_finger" />
    <origin xyz="0 -0.015 0.040" rpy="0 0 0" />
    <axis xyz="0 1 0" />
    <limit lower="1.08" upper="3.14" effort="2" velocity="1.0" />
    <dynamics damping="0.1" friction="0.05" />
    <mimic joint="gripper_left_finger_joint" multiplier="1" offset="0" />
  </joint>

  
  <link name="gripper_right_finger">
    <visual><origin xyz="0 0 0" rpy="0 0 0" /><geometry><mesh filename="file:///home/roarm_m3/roarm_isaac_clean/assets/roarm_m3/meshes/visual/gripper_right_finger.stl" scale="1 1 1" /></geometry><material name="gray" /></visual><collision><origin xyz="0 0 0" rpy="0 0 0" /><geometry><mesh filename="file:///home/roarm_m3/roarm_isaac_clean/assets/roarm_m3/meshes/collision/gripper_right_finger.stl" scale="1 1 1" /></geometry></collision><inertial><mass value="0.0100" /><origin xyz="0.0000 0.0000 0.0000" rpy="0 0 0" /><inertia ixx="0.00000167" iyy="0.00000142" izz="0.00000042" ixy="0.00000000" ixz="0.00000000" iyz="0.00000000" /></inertial></link>

  
  <joint name="gripper_to_tcp" type="fixed">
    <parent link="gripper_base" />
    <child link="tcp" />
    <origin xyz="0.05 0 0.040" rpy="0 0 0" />
  </joint>

  <link name="tcp"><inertial><mass value="0.0100" /><origin xyz="0.0000 0.0000 0.0000" rpy="0 0 0" /><inertia ixx="0.00000017" iyy="0.00000017" izz="0.00000017" ixy="0.00000000" ixz="0.00000000" iyz="0.00000000" /></inertial></link>

</robot>